Workbook
Name Slicer_City: #N/A
Name Slicer_Gender: #N/A

Sheet RawData
A1: EmployeeID | B1: Name | C1: Gender | D1: Age | E1: Department | F1: JobRole | G1: DateOfJoining | H1: MonthlyIncome | I1: MaritalStatus | J1: Education | K1: City | L1: BusinessTravel | M1: DistanceFromHome_KM | N1: OverTime | O1: JobSatisfaction | P1: EnvironmentSatisfaction | Q1: WorkLifeBalance | R1: PerformanceRating | S1: TrainingTimesLastYear | T1: NumCompaniesWorked | U1: PercentSalaryHike | V1: ManagerName | W1: Attrition | X1: LastWorkingDate
A2: EMP1052 | B2: Matthew Rivera | C2: M | D2: 39 | E2: Research & Development | F2: research director | G2: 2016/05/06 | H2: 124035 | I2: Married | J2: Master's | K2: Pune | L2: Travel_Frequently | M2: 11 | N2: No | O2: 1 | P2: 4 | Q2: 3 | R2: 4 | S2: 0 | T2: 4 | U2: 16 | V2: Michelle Evans | W2: No
A3: EMP1523 | B3: Kevin Sullivan | D3: 38 | E3: Human Resources | F3: HR EXECUTIVE | G3: 06/19/2020 | H3: ₹51,334 | I3: Single | J3: Master's | K3: Pune | L3: Travel_Rarely | M3: 27 | N3: No | O3: 1 | P3: 3 | Q3: 2 | R3: 3 | S3: 6 | T3: 2 | U3: 13 | V3: Kimberly Lutz | W3: Yes | X3: 30-01-2026
A4: EMP1180 | B4: Christopher Guerra | C4: Male | D4: 39 | E4: Research & Development | F4: Research Scientist | G4: 03/02/2023 | I4: Divorced | J4: Diploma | K4: Mumbai | L4: Travel_Rarely | M4: 19 | N4: Yes | O4: 4 | P4: 3 | Q4: 1 | R4: 4 | S4: 2 | T4: 1 | U4: 24 | V4: Carol Kim | W4: No
A5: EMP2173 | B5: Kyle Horton | C5: Female | D5: 31 | E5: Research & Development | F5: Lab Technician | G5: 08/02/2013 | H5: 86840 | I5: Divorced | J5: Bachelor's | K5: Pune | L5: Non-Travel | M5: 35 | N5: Yes | O5: 4 | P5: 4 | Q5: 2 | S5: 4 | T5: 2 | U5: 12 | V5: Rebecca Benson | W5: Yes | X5: 03/07/2014
A6: EMP1938 | B6: Peter Keller | C6: female | E6: Research & Development | F6: Lab Technician | G6: 03/26/2021 | I6: Single | J6: Bachelor's | K6: Mumbai | L6: Travel_Rarely | M6: 42 | N6: No | O6: 2 | P6: 2 | Q6: 2 | R6: 2 | S6: 5 | T6: 8 | U6: 16 | V6: Mark Reeves | W6: Yes | X6: 18-02-2026
A7: EMP2152 | B7: John Moore | C7: male | D7: 32 | E7: Research & Development | F7: Manufacturing Technician | G7: 06/16/2021 | H7: 86510 | I7: Married | J7: Master's | K7: Noida | L7: Non-Travel | M7: 29 | N7: Yes | O7: 3 | P7: 1 | Q7: 3 | R7: 1 | S7: 3 | T7: 6 | U7: 17 | V7: James Evans | W7: No
A8: EMP1206 | B8: Danielle Wilson | C8: F | D8: 41 | E8: Research & Development | F8: Lab Technician | G8: 08/21/2022 | I8: Single | J8: Master's | K8: Bangalore | L8: Travel_Rarely | M8: 24 | N8: No | O8: 4 | P8: 4 | Q8: 1 | R8: 3 | S8: 5 | T8: 0 | U8: 18 | V8: Mr. Justin Green III | W8: No
A9: EMP2090 | B9: Michael Hardy | C9: Male | D9: 27 | E9: IT | F9: System Administrator | G9: 28-11-2024 | H9: 52459 | I9: Married | J9: Bachelor's | K9: Pune | L9: Non-Travel | M9: 1 | N9: No | O9: 3 | P9: 4 | Q9: 2 | R9: 3 | S9: 4 | T9: 0 | U9: 18 | V9: Lance Melton | W9: No
A10: EMP1657 | B10: Logan Newton | C10: Female | D10: 30 | E10: Finance | F10: ACCOUNTANT | G10: 09-07-2020 | H10: 62654 | I10: Divorced | J10: PhD | K10: Gurgaon | L10: Travel_Rarely | M10: 44 | N10: No | O10: 3 | P10: 1 | Q10: 1 | R10: 3 | S10: 3 | T10: 1 | U10: 21 | V10: Sheri Buchanan | W10: No
A11: EMP2114 | B11: Nicholas Johnston | C11: Female | D11: 39 | E11: SALES | F11: SALES EXECUTIVE | G11: 2021/10/13 | H11: 41735 | I11: Single | K11: Ahmedabad | L11: Travel_Rarely | M11: 2 | N11: No | O11: 2 | P11: 2 | R11: 4 | S11: 6 | T11: 6 | U11: 20 | V11: Brittany Clements MD | W11: No
A12: EMP1035 | B12: Elizabeth Stewart | C12: Male | D12: 28 | E12: Research & Development | F12: Research Scientist | G12: 2022/11/17 | H12: ₹60,333 | I12: Married | J12: Bachelor's | K12: Hyderabad | L12: Travel_Frequently | M12: 4 | N12: No | O12: 2 | P12: 4 | Q12: 2 | R12: 3 | S12: 0 | T12: 8 | U12: 21 | V12: Jimmy Murillo | W12: No
A13: EMP1736 | B13: Margaret Erickson | C13: Female | D13: 31 | E13: Research & Development | F13: Research Scientist | G13: 06/14/2013 | H13: 111457 | I13: Single | J13: Diploma | K13: Noida | L13: Travel_Frequently | M13: 34 | N13: Yes | O13: 1 | P13: 2 | Q13: 1 | R13: 3 | S13: 0 | T13: 4 | U13: 11 | V13: Matthew Yoder | W13: Yes | X13: 07-10-2024
A14: EMP1064 | B14: David Benson | C14: F | D14: 40 | E14: sales | F14: Sales Manager | G14: 2022/03/15 | H14: 57034 | I14: Married | J14: Bachelor's | K14: Mumbai | L14: Travel_Rarely | M14: 22 | N14: No | O14: 3 | P14: 1 | Q14: 4 | R14: 2 | S14: 1 | T14: 8 | U14: 22 | V14: Jason Daniels | W14: No
A15: EMP1642 | B15: Jonathan Ellis | C15: M | D15: 39 | E15: Sales | F15: sales representative | G15: 2025/06/25 | H15: 75286 | I15: Divorced | J15: PhD | K15: Delhi | L15: Non-Travel | M15: 39 | N15: No | O15: 2 | P15: 4 | Q15: 3 | R15: 4 | S15: 2 | T15: 4 | U15: 19 | V15: Joseph Cook | W15: Yes | X15: 2025/07/04
A16: EMP1762 | B16: Anna Cox | C16: M | D16: 37 | E16: Human Resources | F16: HR Manager | G16: 01/07/2023 | H16: 65329 | I16: Single | J16: Bachelor's | K16: Bangalore | L16: Non-Travel | M16: 37 | N16: No | O16: 4 | P16: 2 | Q16: 4 | R16: 4 | S16: 0 | T16: 7 | U16: 16 | V16: Colleen Townsend | W16: No
A17: EMP1928 | B17: Luke Martinez | C17: Female | D17: 26 | E17: IT | F17: IT Support | G17: 03-01-2015 | H17: 96042 | I17: Single | J17: High School | K17: Hyderabad | L17: Non-Travel | M17: 16 | N17: Yes | O17: 4 | P17: 1 | Q17: 3 | R17: 3 | S17: 2 | T17: 5 | U17: 21 | V17: Gerald Kelly | W17: No
A18: EMP1455 | B18: Joseph Williams | C18: female | D18: 19 | E18: human resources | F18: HR Executive | G18: 07/03/2026 | H18: ₹29,667 | I18: Married | J18: Master's | K18: Mumbai | L18: Non-Travel | M18: 32 | N18: No | O18: 4 | P18: 1 | Q18: 2 | R18: 3 | S18: 4 | T18: 8 | U18: 13 | V18: Alicia Norris | W18: Yes | X18: 2026/08/11
A19: EMP1356 | B19: Pamela Best | C19: Female | D19: 41 | E19: Sales | G19: 26-02-2023 | H19: 86947 | I19: Divorced | J19: Master's | K19: Mumbai | L19: Travel_Frequently | M19: 2 | N19: Yes | O19: 2 | P19: 3 | Q19: 3 | R19: 3 | S19: 5 | T19: 2 | U19: 14 | W19: No
A20: EMP2073 | B20: John Davidson | C20: Female | D20: 30 | E20: Finance | F20: Auditor | G20: 09-06-2020 | H20: ₹134,761 | I20: Single | J20: PhD | K20: Hyderabad | L20: Travel_Frequently | M20: 34 | N20: No | O20: 1 | P20: 2 | Q20: 4 | R20: 4 | S20: 6 | T20: 3 | U20: 18 | V20: Andrew Dorsey | W20: No
A21: EMP1446 | B21: Jason Hudson | C21: Female | D21: 38 | E21: IT | F21: devops engineer | G21: 10 Mar 2025 | H21: ₹132,335 | I21: Married | J21: Bachelor's | K21: Chennai | L21: Travel_Rarely | M21: 1 | N21: Yes | P21: 3 | Q21: 4 | R21: 2 | S21: 6 | T21: 2 | U21: 21 | V21: Mike Maxwell | W21: Yes | X21: 2025/11/11
A22: EMP1351 | B22: Angelica Garcia | C22: M | D22: 33 | E22: Research & Development | F22: lab technician | G22: 11/21/2022 | H22: ₹69,167 | I22: Single | J22: Bachelor's | K22: Chennai | L22: Travel_Frequently | M22: 24 | N22: Yes | O22: 1 | P22: 4 | Q22: 1 | R22: 1 | S22: 1 | T22: 7 | U22: 23 | W22: Yes | X22: 2025/02/11
A23: EMP1173 | B23: Kyle Mccormick | C23: male | D23: 19 | E23: Finance | F23: accountant | G23: 2021/04/27 | H23: 87597 | I23: Married | J23: Master's | K23: Mumbai | L23: Travel_Rarely | M23: 4 | N23: No | O23: 1 | P23: 4 | Q23: 1 | R23: 5 | S23: 2 | T23: 1 | U23: 17 | V23: Michael Mitchell | W23: Yes | X23: 02-09-2021
A24: EMP1514 | B24: Kimberly Arroyo | C24: F | D24: 32 | E24: Research & Development | F24: Research Scientist | G24: 17-03-2016 | I24: Single | J24: Bachelor's | K24: Hyderabad | L24: Non-Travel | N24: No | O24: 2 | P24: 4 | Q24: 4 | R24: 3 | S24: 5 | T24: 5 | U24: 22 | V24: Stephanie Cooper | W24: No
A25: EMP1628 | B25: Andrew Fernandez | C25: male | D25: 32 | E25: Research & Development | F25: Research Director | G25: 23-11-2013 | H25: 68416 | I25: Divorced | J25: Bachelor's | K25: Hyderabad | L25: Non-Travel | M25: 8 | N25: No | O25: 3 | P25: 4 | Q25: 1 | R25: 4 | S25: 5 | T25: 1 | U25: 25 | V25: Connie Williams | W25: No
A26: EMP1569 | B26: Louis Diaz | C26: Female | D26: 41 | E26: IT | F26: System Administrator | G26: 07-02-2019 | H26: 113587 | I26: Married | J26: High School | K26: Mumbai | L26: Non-Travel | O26: 4 | P26: 4 | Q26: 2 | R26: 4 | S26: 2 | T26: 8 | U26: 13 | V26: Michael Watson | W26: No
A27: EMP1791 | B27: Richard Jackson | C27: female | D27: 38 | E27: Marketing | F27: marketing executive | G27: 07/17/2015 | I27: Single | J27: Diploma | K27: Kolkata | L27: Non-Travel | M27: 32 | N27: No | O27: 2 | P27: 3 | Q27: 2 | R27: 3 | S27: 2 | T27: 4 | U27: 21 | V27: Patricia Williams | W27: Yes | X27: 2020/12/04
A28: EMP1373 | B28: Ashley Moreno | C28: M | D28: 34 | E28: Sales | F28: Sales Manager | G28: 20 Mar 2015 | H28: 101011 | I28: Single | J28: High School | K28: Delhi | L28: Travel_Rarely | M28: 16 | N28: No | O28: 2 | P28: 3 | Q28: 4 | R28: 3 | S28: 2 | T28: 7 | U28: 17 | V28: Anthony Shea DDS | W28: No
A29: EMP1254 | B29: Eric Sullivan | C29: Male | D29: 34 | E29: Human Resources | F29: HR Business Partner | G29: 28 Feb 2019 | H29: 68838 | I29: Divorced | J29: Master's | K29: Gurgaon | L29: Travel_Rarely | M29: 7 | N29: No | O29: 3 | P29: 3 | Q29: 4 | R29: 2 | S29: 1 | T29: 3 | U29: 22 | V29: Michele Collins | W29: No
A30: EMP2038 | B30: Susan Suarez | C30: Male | D30: 41 | E30: IT | F30: IT SUPPORT | G30: 07/12/2018 | H30: 132487 | I30: Divorced | J30: Bachelor's | K30: Hyderabad | L30: Non-Travel | M30: 37 | N30: No | O30: 1 | Q30: 2 | R30: 4 | S30: 6 | T30: 2 | U30: 22 | V30: Donna Ibarra | W30: Yes | X30: 03/20/2023
A31: EMP1632 | B31: Luis Fitzgerald | C31: M | D31: 45 | E31: IT | F31: DATA ANALYST | G31: 05/03/2015 | H31: 74430.00 | I31: Divorced | J31: High School | K31: Ahmedabad | L31: Travel_Frequently | M31: 21 | N31: No | O31: 4 | P31: 2 | R31: 4 | S31: 6 | T31: 3 | U31: 15 | V31: Ricardo Morris | W31: No
A32: EMP1453 | B32: Travis Hull | D32: 49 | E32: Sales | F32: Account Manager | G32: 09/06/2017 | H32: 80501 | I32: Single | J32: Master's | K32: Noida | L32: Travel_Rarely | M32: 19 | N32: No | O32: 3 | P32: 1 | Q32: 2 | R32: 4 | S32: 0 | T32: 6 | U32: 20 | V32: Nicholas Anderson | W32: No
A33: EMP1545 | B33: Autumn Smith | C33: Female | D33: 22 | E33: Sales | F33: Sales Manager | G33: 05-06-2021 | I33: Single | J33: Bachelor's | K33: Bangalore | M33: 38 | N33: No | O33: 4 | P33: 1 | Q33: 2 | S33: 3 | V33: Emily Cox | W33: No
A34: EMP1526 | B34: Carol Palmer | C34: Female | D34: 32 | E34: Marketing | F34: Marketing Executive | G34: 27 Apr 2018 | J34: Bachelor's | K34: Kolkata | L34: Non-Travel | M34: 18 | N34: No | O34: 1 | P34: 4 | Q34: 3 | S34: 0 | T34: 2 | U34: 14 | V34: Travis Hopkins | W34: No
A35: EMP1190 | B35: Eric Williams | C35: M | D35: 37 | E35: Research & Development | F35: LAB TECHNICIAN | G35: 12/04/2017 | H35: 54333 | I35: Divorced | J35: Master's | K35: Mumbai | L35: Travel_Rarely | M35: 25 | N35: No | O35: 2 | P35: 3 | Q35: 2 | R35: 3 | S35: 4 | T35: 3 | U35: 24 | V35: Joyce Rodriguez | W35: No
A36: EMP1102 | B36: Jordan Edwards | C36: F | D36: 41 | E36: Research & Development | F36: research director | G36: 2016/06/26 | H36: 87201 | I36: Married | J36: PhD | K36: Delhi | L36: Travel_Rarely | M36: 3 | N36: Yes | O36: 3 | P36: 4 | Q36: 4 | S36: 4 | U36: 12 | V36: Jennifer Robertson | W36: No
A37: EMP1735 | B37: Corey Johnson | C37: F | D37: 34 | E37: IT | F37: software engineer | G37: 12 Jan 2013 | H37: ₹72,007 | I37: Divorced | J37: Master's | K37: Pune | L37: Non-Travel | M37: 41 | N37: No | O37: 1 | P37: 4 | Q37: 4 | R37: 4 | S37: 4 | T37: 3 | U37: 21 | V37: Mary Houston | W37: No
A38: EMP1335 | B38: Anthony Bell | C38: Male | D38: 47 | F38: Sales Executive | G38: 2015/11/09 | H38: 87128.00 | I38: Divorced | J38: High School | L38: Non-Travel | M38: 44 | N38: No | O38: 4 | P38: 2 | Q38: 3 | R38: 4 | S38: 3 | T38: 2 | U38: 25 | V38: Erica Padilla | W38: No
A39: EMP1997 | B39: Robert Hobbs | C39: Female | D39: 58 | E39: IT | F39: Data Analyst | G39: 25-11-2020 | H39: 111382 | I39: Married | J39: Master's | K39: Noida | L39: Travel_Rarely | M39: 39 | N39: No | O39: 3 | P39: 4 | R39: 5 | S39: 3 | T39: 7 | U39: 18 | V39: Timothy Logan | W39: No
A40: EMP1447 | B40: Mr. Christopher Walters | C40: F | D40: 45 | E40: Finance | F40: Accountant | G40: 25 Sep 2011 | H40: 126651 | I40: Divorced | J40: Diploma | K40: Pune | L40: Travel_Rarely | M40: 3 | N40: No | O40: 3 | P40: 3 | Q40: 1 | R40: 3 | S40: 5 | T40: 5 | U40: 15 | V40: Philip Jackson | W40: No
...

Sheet PivotAnalysis
A3: Row Labels | B3: Count of Attrition | C3: Count of Attrition2 | E3: Column Labels
A4: No | B4: 848 | C4: 0.70666667 | E4: No | G4: Yes | I4: Total Count of Attrition | J4: Total Count of Attrition2
A5: Yes | B5: 352 | C5: 0.29333333 | D5: Row Labels | E5: Count of Attrition | F5: Count of Attrition2 | G5: Count of Attrition | H5: Count of Attrition2
A6: Grand Total | B6: 1200 | C6: 1 | D6: Finance | E6: 110 | F6: 0.69620253 | G6: 48 | H6: 0.30379747 | I6: 158 | J6: 1
D7: Human Resources | E7: 66 | F7: 0.74157303 | G7: 23 | H7: 0.25842697 | I7: 89 | J7: 1
D8: It | E8: 153 | F8: 0.72511848 | G8: 58 | H8: 0.27488152 | I8: 211 | J8: 1
D9: Marketing | E9: 63 | F9: 0.63 | G9: 37 | H9: 0.37 | I9: 100 | J9: 1
D10: Not Specified | E10: 22 | F10: 0.6875 | G10: 10 | H10: 0.3125 | I10: 32 | J10: 1
D11: Operations | E11: 27 | F11: 0.64285714 | G11: 15 | H11: 0.35714286 | I11: 42 | J11: 1
D12: Research & Development | E12: 223 | F12: 0.71474359 | G12: 89 | H12: 0.28525641 | I12: 312 | J12: 1
D13: Sales | E13: 184 | F13: 0.71875 | G13: 72 | H13: 0.28125 | I13: 256 | J13: 1
D14: Grand Total | E14: 848 | F14: 0.70666667 | G14: 352 | H14: 0.29333333 | I14: 1200 | J14: 1
B18: Column Labels
B19: Count of Attrition | D19: Count of Attrition2 | F19: Total Count of Attrition | G19: Total Count of Attrition2
A20: Row Labels | B20: No | C20: Yes | D20: No | E20: Yes
A21: 25-34 | B21: 287 | C21: 122 | D21: 0.70171149 | E21: 0.29828851 | F21: 409 | G21: 1
A22: 35-44 | B22: 358 | C22: 139 | D22: 0.72032193 | E22: 0.27967807 | F22: 497 | G22: 1
A23: 45-54 | B23: 109 | C23: 43 | D23: 0.71710526 | E23: 0.28289474 | F23: 152 | G23: 1
A24: 55+ | B24: 6 | C24: 4 | D24: 0.6 | E24: 0.4 | F24: 10 | G24: 1
A25: Under 25 | B25: 88 | C25: 44 | D25: 0.66666667 | E25: 0.33333333 | F25: 132 | G25: 1
A26: Grand Total | B26: 848 | C26: 352 | D26: 0.70666667 | E26: 0.29333333 | F26: 1200 | G26: 1
B30: Column Labels
B31: Count of Attrition | D31: Count of Attrition2 | F31: Total Count of Attrition | G31: Total Count of Attrition2
A32: Row Labels | B32: No | C32: Yes | D32: No | E32: Yes
A33: High | B33: 419 | C33: 181 | D33: 0.69833333 | E33: 0.30166667 | F33: 600 | G33: 1
A34: Low | B34: 1 | C34: 1 | D34: 0.5 | E34: 0.5 | F34: 2 | G34: 1
A35: Medium | B35: 198 | C35: 86 | D35: 0.6971831 | E35: 0.3028169 | F35: 284 | G35: 1
A36: Very High | B36: 230 | C36: 84 | D36: 0.73248408 | E36: 0.26751592 | F36: 314 | G36: 1
A37: Grand Total | B37: 848 | C37: 352 | D37: 0.70666667 | E37: 0.29333333 | F37: 1200 | G37: 1
B41: Column Labels
B42: No | D42: Yes | F42: Total Count of Attrition | G42: Total Count of Attrition2
A43: Row Labels | B43: Count of Attrition | C43: Count of Attrition2 | D43: Count of Attrition | E43: Count of Attrition2
A44: No | B44: 716 | C44: 0.83352736 | D44: 143 | E44: 0.16647264 | F44: 859 | G44: 1
A45: Yes | B45: 132 | C45: 0.38709677 | D45: 209 | E45: 0.61290323 | F45: 341 | G45: 1
A46: Grand Total | B46: 848 | C46: 0.70666667 | D46: 352 | E46: 0.29333333 | F46: 1200 | G46: 1
B50: Column Labels
B51: No | D51: Yes | F51: Total Count of Attrition | G51: Total Count of Attrition2
A52: Row Labels | B52: Count of Attrition | C52: Count of Attrition2 | D52: Count of Attrition | E52: Count of Attrition2
A53: 1 | B53: 137 | C53: 0.49103943 | D53: 142 | E53: 0.50896057 | F53: 279 | G53: 1
A54: 2 | B54: 151 | C54: 0.53736655 | D54: 130 | E54: 0.46263345 | F54: 281 | G54: 1
...

Sheet KPI
A1: HR Workforce KPI Metrics | D1: Replacement Months | E1: Estimated Attrition Cost
E2: =B11 -> 170702382
A3: Total Employees | B3: =COUNTA(EmployeeData[EmployeeID]) -> 1200 | D3: 3 | E3: 85351191
A4: Employees Left | B4: =SUM(EmployeeData[Attrition Flag]) -> 352 | D4: 6 | E4: 170702382
A5: Active Employees | B5: =B3-B4 -> 848 | D5: 9 | E5: 256053573
A6: Attrition Rate | B6: =B4/B3 -> 0.29333333 | D6: 12 | E6: 341404764
A7: Average Tenure (Years) | B7: =AVERAGE(EmployeeData[Tenure Years]) -> 6.12
A8: Average Monthly Income | B8: =AVERAGE(EmployeeData[MonthlyIncome]) -> 82402.143
A9: Average Satisfaction Score | B9: =AVERAGE(EmployeeData[Satisfaction Score]) -> 2.555425
A10: Replacement Cost (Months) | B10: 6
A11: Estimated Attrition Cost | B11: =SUMIFS(EmployeeData[MonthlyIncome],EmployeeData[Attrition],"Yes")*$B$10 -> 170702382

Sheet Documentation
A1: HR WORKFORCE ANALYTICS & ATTRITION DASHBOARD
A2: Project Documentation
A4: Project Objective | B4: Analyze employee attrition, identify major risk factors, and estimate its financial impact.
A5: Dataset Size | B5: =KPI!B3&" employee records" -> 1200 employee records
A6: Tools Used | B6: Power Query, Excel Tables, Advanced Formulas, PivotTables, Charts, Slicers, and What-If Analysis
A7: Main Outcome | B7: Identified the employee groups with the highest attrition risk and created an interactive HR dashboard.
A9: Key Insights
A10: 1 | B10: Overall employee attrition rate is 29.33%.
A11: 2 | B11: Employees working overtime have a 61.29% attrition rate, compared with 16.65% for employees without overtime.
A12: 3 | B12: Low-satisfaction employees have a 55.86% attrition rate, while high-satisfaction employees have only 13.61%.
A13: 4 | B13: Marketing has the highest department attrition rate at 37.00%.
A14: 5 | B14: The 55+ age group has the highest rate at 40.00%, but the group contains only 10 employees, so the result should be interpreted carefully.
A16: How to Use the Dashboard
A17: 1 | B17: Use the Gender and City slicers to filter all charts.
A18: 2 | B18: Click the filter-clear icon in each slicer to return to the complete workforce view.
A19: 3 | B19: Review both attrition percentage and employee count before drawing conclusions.
A21: Important Assumption
A22: Attrition Cost | B22: This assumption can be changed in cell B10 of the KPI sheet.
A58: Note: KPI cards show overall workforce metrics; charts respond to the Gender and City slicers.

Sheet Dashboard
A1: HR WORKFORCE ANALYTICS & ATTRITION DASHBOARD
P2: Status | Q2: Employee Count | S2: OverTime | T2: Attrition Rate | V2: Satisfaction Level | W2: Attrition Rate | Y2: Age Band | Z2: Attrition Rate | AB2: Salary Band | AC2: Attrition Rate
A3: TOTAL EMPLOYEES | D3: ATTRITION RATE | G3: AVERAGE TENURE | J3: ESTIMATED ATTRITION COST (₹ CRORE) | P3: Active | Q3: =GETPIVOTDATA("Count of Attrition",PivotAnalysis!$A$3,"Attrition","No") -> 848 | S3: No | T3: =IFERROR(GETPIVOTDATA("Count of Attrition",PivotAnalysis!$A$43,"OverTime",S3,"Attrition","Yes")/GETPIVOTDATA("Count of Attrition",PivotAnalysis!$A$43,"OverTime",S3),0) -> 0.16647264 | V3: High | W3: =IFERROR(GETPIVOTDATA("Count of Attrition",PivotAnalysis!$A$62,"Satisfaction Level",V3,"Attrition","Yes")/GETPIVOTDATA("Count of Attrition",PivotAnalysis!$A$62,"Satisfaction Level",V3),0) -> 0.13613861 | Y3: 25-34 | Z3: =IFERROR(GETPIVOTDATA("Count of Attrition",PivotAnalysis!$A$20,"Age Band",Y3,"Attrition","Yes")/GETPIVOTDATA("Count of Attrition",PivotAnalysis!$A$20,"Age Band",Y3),0) -> 0.29828851 | AB3: High | AC3: =IFERROR(GETPIVOTDATA("Count of Attrition",PivotAnalysis!$A$32,"Salary Band",AB3,"Attrition","Yes")/GETPIVOTDATA("Count of Attrition",PivotAnalysis!$A$32,"Salary Band",AB3),0) -> 0.30166667
P4: Left | Q4: =GETPIVOTDATA("Count of Attrition",PivotAnalysis!$A$3,"Attrition","Yes") -> 352 | S4: Yes | T4: =IFERROR(GETPIVOTDATA("Count of Attrition",PivotAnalysis!$A$43,"OverTime",S4,"Attrition","Yes")/GETPIVOTDATA("Count of Attrition",PivotAnalysis!$A$43,"OverTime",S4),0) -> 0.61290323 | V4: Low | W4: =IFERROR(GETPIVOTDATA("Count of Attrition",PivotAnalysis!$A$62,"Satisfaction Level",V4,"Attrition","Yes")/GETPIVOTDATA("Count of Attrition",PivotAnalysis!$A$62,"Satisfaction Level",V4),0) -> 0.55862069 | Y4: 35-44 | Z4: =IFERROR(GETPIVOTDATA("Count of Attrition",PivotAnalysis!$A$20,"Age Band",Y4,"Attrition","Yes")/GETPIVOTDATA("Count of Attrition",PivotAnalysis!$A$20,"Age Band",Y4),0) -> 0.27967807 | AB4: Low | AC4: =IFERROR(GETPIVOTDATA("Count of Attrition",PivotAnalysis!$A$32,"Salary Band",AB4,"Attrition","Yes")/GETPIVOTDATA("Count of Attrition",PivotAnalysis!$A$32,"Salary Band",AB4),0) -> 0.5
A5: =KPI!B3 -> 1200 | D5: =KPI!B6 -> 0.29333333 | G5: =KPI!B7 -> 6.12 | J5: =KPI!B11/10000000 -> 17.070238 | V5: Medium | W5: =IFERROR(GETPIVOTDATA("Count of Attrition",PivotAnalysis!$A$62,"Satisfaction Level",V5,"Attrition","Yes")/GETPIVOTDATA("Count of Attrition",PivotAnalysis!$A$62,"Satisfaction Level",V5),0) -> 0.33179724 | Y5: 45-54 | Z5: =IFERROR(GETPIVOTDATA("Count of Attrition",PivotAnalysis!$A$20,"Age Band",Y5,"Attrition","Yes")/GETPIVOTDATA("Count of Attrition",PivotAnalysis!$A$20,"Age Band",Y5),0) -> 0.28289474 | AB5: Medium | AC5: =IFERROR(GETPIVOTDATA("Count of Attrition",PivotAnalysis!$A$32,"Salary Band",AB5,"Attrition","Yes")/GETPIVOTDATA("Count of Attrition",PivotAnalysis!$A$32,"Salary Band",AB5),0) -> 0.3028169
Y6: 55+ | Z6: =IFERROR(GETPIVOTDATA("Count of Attrition",PivotAnalysis!$A$20,"Age Band",Y6,"Attrition","Yes")/GETPIVOTDATA("Count of Attrition",PivotAnalysis!$A$20,"Age Band",Y6),0) -> 0.4 | AB6: Very High | AC6: =IFERROR(GETPIVOTDATA("Count of Attrition",PivotAnalysis!$A$32,"Salary Band",AB6,"Attrition","Yes")/GETPIVOTDATA("Count of Attrition",PivotAnalysis!$A$32,"Salary Band",AB6),0) -> 0.26751592
P7: Department | Q7: Attrition Rate | Y7: Under 25 | Z7: =IFERROR(GETPIVOTDATA("Count of Attrition",PivotAnalysis!$A$20,"Age Band",Y7,"Attrition","Yes")/GETPIVOTDATA("Count of Attrition",PivotAnalysis!$A$20,"Age Band",Y7),0) -> 0.33333333
P8: Finance | Q8: =IFERROR(GETPIVOTDATA("Count of Attrition",PivotAnalysis!$D$5,"Department",P8,"Attrition","Yes")/GETPIVOTDATA("Count of Attrition",PivotAnalysis!$D$5,"Department",P8),0) -> 0.30379747
P9: Human Resources | Q9: =IFERROR(GETPIVOTDATA("Count of Attrition",PivotAnalysis!$D$5,"Department",P9,"Attrition","Yes")/GETPIVOTDATA("Count of Attrition",PivotAnalysis!$D$5,"Department",P9),0) -> 0.25842697
P10: It | Q10: =IFERROR(GETPIVOTDATA("Count of Attrition",PivotAnalysis!$D$5,"Department",P10,"Attrition","Yes")/GETPIVOTDATA("Count of Attrition",PivotAnalysis!$D$5,"Department",P10),0) -> 0.27488152
P11: Marketing | Q11: =IFERROR(GETPIVOTDATA("Count of Attrition",PivotAnalysis!$D$5,"Department",P11,"Attrition","Yes")/GETPIVOTDATA("Count of Attrition",PivotAnalysis!$D$5,"Department",P11),0) -> 0.37
P12: Not Specified | Q12: =IFERROR(GETPIVOTDATA("Count of Attrition",PivotAnalysis!$D$5,"Department",P12,"Attrition","Yes")/GETPIVOTDATA("Count of Attrition",PivotAnalysis!$D$5,"Department",P12),0) -> 0.3125
P13: Operations | Q13: =IFERROR(GETPIVOTDATA("Count of Attrition",PivotAnalysis!$D$5,"Department",P13,"Attrition","Yes")/GETPIVOTDATA("Count of Attrition",PivotAnalysis!$D$5,"Department",P13),0) -> 0.35714286
P14: Research & Development | Q14: =IFERROR(GETPIVOTDATA("Count of Attrition",PivotAnalysis!$D$5,"Department",P14,"Attrition","Yes")/GETPIVOTDATA("Count of Attrition",PivotAnalysis!$D$5,"Department",P14),0) -> 0.28525641
P15: Sales | Q15: =IFERROR(GETPIVOTDATA("Count of Attrition",PivotAnalysis!$D$5,"Department",P15,"Attrition","Yes")/GETPIVOTDATA("Count of Attrition",PivotAnalysis!$D$5,"Department",P15),0) -> 0.28125

Sheet CleanData
A1: EmployeeID | B1: Name | C1: Gender | D1: Age | E1: Department | F1: JobRole | G1: DateOfJoining | H1: MonthlyIncome | I1: MaritalStatus | J1: Education | K1: City | L1: BusinessTravel | M1: DistanceFromHome_KM | N1: OverTime | O1: JobSatisfaction | P1: EnvironmentSatisfaction | Q1: WorkLifeBalance | R1: PerformanceRating | S1: TrainingTimesLastYear | T1: NumCompaniesWorked | U1: PercentSalaryHike | V1: ManagerName | W1: Attrition | X1: LastWorkingDate | Y1: Age Band | Z1: Tenure Years | AA1: Salary Band | AB1: Attrition Flag | AC1: Tenure Band | AD1: Satisfaction Score | AE1: Satisfaction Level
A2: EMP1052 | B2: Matthew Rivera | C2: Male | D2: 39 | E2: Research & Development | F2: Research Director | G2: 42496 | H2: 124035 | I2: Married | J2: Master's | K2: Pune | L2: Travel_Frequently | M2: 11 | N2: No | O2: 1 | P2: 4 | Q2: 3 | R2: 4 | S2: 0 | T2: 4 | U2: 16 | V2: Michelle Evans | W2: No | Y2: =IF(EmployeeData[[#This Row],[Age]]<25,"Under 25",IF(EmployeeData[[#This Row],[Age]]<=34,"25-34",IF(EmployeeData[[#This Row],[Age]]<=44,"35-44",IF(EmployeeData[[#This Row],[Age]]<=54,"45-54","55+")))) -> 35-44 | Z2: =DATEDIF(EmployeeData[[#This Row],[DateOfJoining]],IF(AND(EmployeeData[[#This Row],[Attrition]]="Yes",EmployeeData[[#This Row],[LastWorkingDate]]<>""),EmployeeData[[#This Row],[LastWorkingDate]],TODAY()),"Y") -> 10 | AA2: =IF(EmployeeData[[#This Row],[MonthlyIncome]]<30000,"Low",IF(EmployeeData[[#This Row],[MonthlyIncome]]<=60000,"Medium",IF(EmployeeData[[#This Row],[MonthlyIncome]]<=100000,"High","Very High"))) -> Very High | AB2: =IF(EmployeeData[[#This Row],[Attrition]]="Yes",1,0) -> 0 | AC2: =IF(EmployeeData[[#This Row],[Tenure Years]]<1,"Less than 1 Year",IF(EmployeeData[[#This Row],[Tenure Years]]<=3,"1-3 Years",IF(EmployeeData[[#This Row],[Tenure Years]]<=5,"4-5 Years",IF(EmployeeData[[#This Row],[Tenure Years]]<=10,"6-10 Years","More than 10 Years")))) -> 6-10 Years | AD2: =ROUND(AVERAGE(EmployeeData[[#This Row],[JobSatisfaction]],EmployeeData[[#This Row],[EnvironmentSatisfaction]],EmployeeData[[#This Row],[WorkLifeBalance]]),2) -> 2.67 | AE2: =IF(EmployeeData[[#This Row],[Satisfaction Score]]<2,"Low",IF(EmployeeData[[#This Row],[Satisfaction Score]]<3,"Medium","High")) -> Medium
A3: EMP1523 | B3: Kevin Sullivan | C3: Not Specified | D3: 38 | E3: Human Resources | F3: Hr Executive | G3: 44001 | H3: 51334 | I3: Single | J3: Master's | K3: Pune | L3: Travel_Rarely | M3: 27 | N3: No | O3: 1 | P3: 3 | Q3: 2 | R3: 3 | S3: 6 | T3: 2 | U3: 13 | V3: Kimberly Lutz | W3: Yes | X3: 46052 | Y3: =IF(EmployeeData[[#This Row],[Age]]<25,"Under 25",IF(EmployeeData[[#This Row],[Age]]<=34,"25-34",IF(EmployeeData[[#This Row],[Age]]<=44,"35-44",IF(EmployeeData[[#This Row],[Age]]<=54,"45-54","55+")))) -> 35-44 | Z3: =DATEDIF(EmployeeData[[#This Row],[DateOfJoining]],IF(AND(EmployeeData[[#This Row],[Attrition]]="Yes",EmployeeData[[#This Row],[LastWorkingDate]]<>""),EmployeeData[[#This Row],[LastWorkingDate]],TODAY()),"Y") -> 5 | AA3: =IF(EmployeeData[[#This Row],[MonthlyIncome]]<30000,"Low",IF(EmployeeData[[#This Row],[MonthlyIncome]]<=60000,"Medium",IF(EmployeeData[[#This Row],[MonthlyIncome]]<=100000,"High","Very High"))) -> Medium | AB3: =IF(EmployeeData[[#This Row],[Attrition]]="Yes",1,0) -> 1 | AC3: =IF(EmployeeData[[#This Row],[Tenure Years]]<1,"Less than 1 Year",IF(EmployeeData[[#This Row],[Tenure Years]]<=3,"1-3 Years",IF(EmployeeData[[#This Row],[Tenure Years]]<=5,"4-5 Years",IF(EmployeeData[[#This Row],[Tenure Years]]<=10,"6-10 Years","More than 10 Years")))) -> 4-5 Years | AD3: =ROUND(AVERAGE(EmployeeData[[#This Row],[JobSatisfaction]],EmployeeData[[#This Row],[EnvironmentSatisfaction]],EmployeeData[[#This Row],[WorkLifeBalance]]),2) -> 2 | AE3: =IF(EmployeeData[[#This Row],[Satisfaction Score]]<2,"Low",IF(EmployeeData[[#This Row],[Satisfaction Score]]<3,"Medium","High")) -> Medium
A4: EMP1180 | B4: Christopher Guerra | C4: Male | D4: 39 | E4: Research & Development | F4: Research Scientist | G4: 44987 | H4: 83084 | I4: Divorced | J4: Diploma | K4: Mumbai | L4: Travel_Rarely | M4: 19 | N4: Yes | O4: 4 | P4: 3 | Q4: 1 | R4: 4 | S4: 2 | T4: 1 | U4: 24 | V4: Carol Kim | W4: No | Y4: =IF(EmployeeData[[#This Row],[Age]]<25,"Under 25",IF(EmployeeData[[#This Row],[Age]]<=34,"25-34",IF(EmployeeData[[#This Row],[Age]]<=44,"35-44",IF(EmployeeData[[#This Row],[Age]]<=54,"45-54","55+")))) -> 35-44 | Z4: =DATEDIF(EmployeeData[[#This Row],[DateOfJoining]],IF(AND(EmployeeData[[#This Row],[Attrition]]="Yes",EmployeeData[[#This Row],[LastWorkingDate]]<>""),EmployeeData[[#This Row],[LastWorkingDate]],TODAY()),"Y") -> 3 | AA4: =IF(EmployeeData[[#This Row],[MonthlyIncome]]<30000,"Low",IF(EmployeeData[[#This Row],[MonthlyIncome]]<=60000,"Medium",IF(EmployeeData[[#This Row],[MonthlyIncome]]<=100000,"High","Very High"))) -> High | AB4: =IF(EmployeeData[[#This Row],[Attrition]]="Yes",1,0) -> 0 | AC4: =IF(EmployeeData[[#This Row],[Tenure Years]]<1,"Less than 1 Year",IF(EmployeeData[[#This Row],[Tenure Years]]<=3,"1-3 Years",IF(EmployeeData[[#This Row],[Tenure Years]]<=5,"4-5 Years",IF(EmployeeData[[#This Row],[Tenure Years]]<=10,"6-10 Years","More than 10 Years")))) -> 1-3 Years | AD4: =ROUND(AVERAGE(EmployeeData[[#This Row],[JobSatisfaction]],EmployeeData[[#This Row],[EnvironmentSatisfaction]],EmployeeData[[#This Row],[WorkLifeBalance]]),2) -> 2.67 | AE4: =IF(EmployeeData[[#This Row],[Satisfaction Score]]<2,"Low",IF(EmployeeData[[#This Row],[Satisfaction Score]]<3,"Medium","High")) -> Medium
A5: EMP2173 | B5: Kyle Horton | C5: Female | D5: 31 | E5: Research & Development | F5: Lab Technician | G5: 41488 | H5: 86840 | I5: Divorced | J5: Bachelor's | K5: Pune | L5: Non-Travel | M5: 35 | N5: Yes | O5: 4 | P5: 4 | Q5: 2 | R5: 3 | S5: 4 | T5: 2 | U5: 12 | V5: Rebecca Benson | W5: Yes | X5: 41705 | Y5: =IF(EmployeeData[[#This Row],[Age]]<25,"Under 25",IF(EmployeeData[[#This Row],[Age]]<=34,"25-34",IF(EmployeeData[[#This Row],[Age]]<=44,"35-44",IF(EmployeeData[[#This Row],[Age]]<=54,"45-54","55+")))) -> 25-34 | Z5: =DATEDIF(EmployeeData[[#This Row],[DateOfJoining]],IF(AND(EmployeeData[[#This Row],[Attrition]]="Yes",EmployeeData[[#This Row],[LastWorkingDate]]<>""),EmployeeData[[#This Row],[LastWorkingDate]],TODAY()),"Y") -> 0 | AA5: =IF(EmployeeData[[#This Row],[MonthlyIncome]]<30000,"Low",IF(EmployeeData[[#This Row],[MonthlyIncome]]<=60000,"Medium",IF(EmployeeData[[#This Row],[MonthlyIncome]]<=100000,"High","Very High"))) -> High | AB5: =IF(EmployeeData[[#This Row],[Attrition]]="Yes",1,0) -> 1 | AC5: =IF(EmployeeData[[#This Row],[Tenure Years]]<1,"Less than 1 Year",IF(EmployeeData[[#This Row],[Tenure Years]]<=3,"1-3 Years",IF(EmployeeData[[#This Row],[Tenure Years]]<=5,"4-5 Years",IF(EmployeeData[[#This Row],[Tenure Years]]<=10,"6-10 Years","More than 10 Years")))) -> Less than 1 Year | AD5: =ROUND(AVERAGE(EmployeeData[[#This Row],[JobSatisfaction]],EmployeeData[[#This Row],[EnvironmentSatisfaction]],EmployeeData[[#This Row],[WorkLifeBalance]]),2) -> 3.33 | AE5: =IF(EmployeeData[[#This Row],[Satisfaction Score]]<2,"Low",IF(EmployeeData[[#This Row],[Satisfaction Score]]<3,"Medium","High")) -> High
A6: EMP1938 | B6: Peter Keller | C6: Female | D6: 35 | E6: Research & Development | F6: Lab Technician | G6: 44281 | H6: 83084 | I6: Single | J6: Bachelor's | K6: Mumbai | L6: Travel_Rarely | M6: 42 | N6: No | O6: 2 | P6: 2 | Q6: 2 | R6: 2 | S6: 5 | T6: 8 | U6: 16 | V6: Mark Reeves | W6: Yes | X6: 46071 | Y6: =IF(EmployeeData[[#This Row],[Age]]<25,"Under 25",IF(EmployeeData[[#This Row],[Age]]<=34,"25-34",IF(EmployeeData[[#This Row],[Age]]<=44,"35-44",IF(EmployeeData[[#This Row],[Age]]<=54,"45-54","55+")))) -> 35-44 | Z6: =DATEDIF(EmployeeData[[#This Row],[DateOfJoining]],IF(AND(EmployeeData[[#This Row],[Attrition]]="Yes",EmployeeData[[#This Row],[LastWorkingDate]]<>""),EmployeeData[[#This Row],[LastWorkingDate]],TODAY()),"Y") -> 4 | AA6: =IF(EmployeeData[[#This Row],[MonthlyIncome]]<30000,"Low",IF(EmployeeData[[#This Row],[MonthlyIncome]]<=60000,"Medium",IF(EmployeeData[[#This Row],[MonthlyIncome]]<=100000,"High","Very High"))) -> High | AB6: =IF(EmployeeData[[#This Row],[Attrition]]="Yes",1,0) -> 1 | AC6: =IF(EmployeeData[[#This Row],[Tenure Years]]<1,"Less than 1 Year",IF(EmployeeData[[#This Row],[Tenure Years]]<=3,"1-3 Years",IF(EmployeeData[[#This Row],[Tenure Years]]<=5,"4-5 Years",IF(EmployeeData[[#This Row],[Tenure Years]]<=10,"6-10 Years","More than 10 Years")))) -> 4-5 Years | AD6: =ROUND(AVERAGE(EmployeeData[[#This Row],[JobSatisfaction]],EmployeeData[[#This Row],[EnvironmentSatisfaction]],EmployeeData[[#This Row],[WorkLifeBalance]]),2) -> 2 | AE6: =IF(EmployeeData[[#This Row],[Satisfaction Score]]<2,"Low",IF(EmployeeData[[#This Row],[Satisfaction Score]]<3,"Medium","High")) -> Medium
A7: EMP2152 | B7: John Moore | C7: Male | D7: 32 | E7: Research & Development | F7: Manufacturing Technician | G7: 44363 | H7: 86510 | I7: Married | J7: Master's | K7: Noida | L7: Non-Travel | M7: 29 | N7: Yes | O7: 3 | P7: 1 | Q7: 3 | R7: 1 | S7: 3 | T7: 6 | U7: 17 | V7: James Evans | W7: No | Y7: =IF(EmployeeData[[#This Row],[Age]]<25,"Under 25",IF(EmployeeData[[#This Row],[Age]]<=34,"25-34",IF(EmployeeData[[#This Row],[Age]]<=44,"35-44",IF(EmployeeData[[#This Row],[Age]]<=54,"45-54","55+")))) -> 25-34 | Z7: =DATEDIF(EmployeeData[[#This Row],[DateOfJoining]],IF(AND(EmployeeData[[#This Row],[Attrition]]="Yes",EmployeeData[[#This Row],[LastWorkingDate]]<>""),EmployeeData[[#This Row],[LastWorkingDate]],TODAY()),"Y") -> 5 | AA7: =IF(EmployeeData[[#This Row],[MonthlyIncome]]<30000,"Low",IF(EmployeeData[[#This Row],[MonthlyIncome]]<=60000,"Medium",IF(EmployeeData[[#This Row],[MonthlyIncome]]<=100000,"High","Very High"))) -> High | AB7: =IF(EmployeeData[[#This Row],[Attrition]]="Yes",1,0) -> 0 | AC7: =IF(EmployeeData[[#This Row],[Tenure Years]]<1,"Less than 1 Year",IF(EmployeeData[[#This Row],[Tenure Years]]<=3,"1-3 Years",IF(EmployeeData[[#This Row],[Tenure Years]]<=5,"4-5 Years",IF(EmployeeData[[#This Row],[Tenure Years]]<=10,"6-10 Years","More than 10 Years")))) -> 4-5 Years | AD7: =ROUND(AVERAGE(EmployeeData[[#This Row],[JobSatisfaction]],EmployeeData[[#This Row],[EnvironmentSatisfaction]],EmployeeData[[#This Row],[WorkLifeBalance]]),2) -> 2.33 | AE7: =IF(EmployeeData[[#This Row],[Satisfaction Score]]<2,"Low",IF(EmployeeData[[#This Row],[Satisfaction Score]]<3,"Medium","High")) -> Medium
A8: EMP1206 | B8: Danielle Wilson | C8: Female | D8: 41 | E8: Research & Development | F8: Lab Technician | G8: 44794 | H8: 83084 | I8: Single | J8: Master's | K8: Bangalore | L8: Travel_Rarely | M8: 24 | N8: No | O8: 4 | P8: 4 | Q8: 1 | R8: 3 | S8: 5 | T8: 0 | U8: 18 | V8: Mr. Justin Green III | W8: No | Y8: =IF(EmployeeData[[#This Row],[Age]]<25,"Under 25",IF(EmployeeData[[#This Row],[Age]]<=34,"25-34",IF(EmployeeData[[#This Row],[Age]]<=44,"35-44",IF(EmployeeData[[#This Row],[Age]]<=54,"45-54","55+")))) -> 35-44 | Z8: =DATEDIF(EmployeeData[[#This Row],[DateOfJoining]],IF(AND(EmployeeData[[#This Row],[Attrition]]="Yes",EmployeeData[[#This Row],[LastWorkingDate]]<>""),EmployeeData[[#This Row],[LastWorkingDate]],TODAY()),"Y") -> 4 | AA8: =IF(EmployeeData[[#This Row],[MonthlyIncome]]<30000,"Low",IF(EmployeeData[[#This Row],[MonthlyIncome]]<=60000,"Medium",IF(EmployeeData[[#This Row],[MonthlyIncome]]<=100000,"High","Very High"))) -> High | AB8: =IF(EmployeeData[[#This Row],[Attrition]]="Yes",1,0) -> 0 | AC8: =IF(EmployeeData[[#This Row],[Tenure Years]]<1,"Less than 1 Year",IF(EmployeeData[[#This Row],[Tenure Years]]<=3,"1-3 Years",IF(EmployeeData[[#This Row],[Tenure Years]]<=5,"4-5 Years",IF(EmployeeData[[#This Row],[Tenure Years]]<=10,"6-10 Years","More than 10 Years")))) -> 4-5 Years | AD8: =ROUND(AVERAGE(EmployeeData[[#This Row],[JobSatisfaction]],EmployeeData[[#This Row],[EnvironmentSatisfaction]],EmployeeData[[#This Row],[WorkLifeBalance]]),2) -> 3 | AE8: =IF(EmployeeData[[#This Row],[Satisfaction Score]]<2,"Low",IF(EmployeeData[[#This Row],[Satisfaction Score]]<3,"Medium","High")) -> High
A9: EMP2090 | B9: Michael Hardy | C9: Male | D9: 27 | E9: It | F9: System Administrator | G9: 45624 | H9: 52459 | I9: Married | J9: Bachelor's | K9: Pune | L9: Non-Travel | M9: 1 | N9: No | O9: 3 | P9: 4 | Q9: 2 | R9: 3 | S9: 4 | T9: 0 | U9: 18 | V9: Lance Melton | W9: No | Y9: =IF(EmployeeData[[#This Row],[Age]]<25,"Under 25",IF(EmployeeData[[#This Row],[Age]]<=34,"25-34",IF(EmployeeData[[#This Row],[Age]]<=44,"35-44",IF(EmployeeData[[#This Row],[Age]]<=54,"45-54","55+")))) -> 25-34 | Z9: =DATEDIF(EmployeeData[[#This Row],[DateOfJoining]],IF(AND(EmployeeData[[#This Row],[Attrition]]="Yes",EmployeeData[[#This Row],[LastWorkingDate]]<>""),EmployeeData[[#This Row],[LastWorkingDate]],TODAY()),"Y") -> 1 | AA9: =IF(EmployeeData[[#This Row],[MonthlyIncome]]<30000,"Low",IF(EmployeeData[[#This Row],[MonthlyIncome]]<=60000,"Medium",IF(EmployeeData[[#This Row],[MonthlyIncome]]<=100000,"High","Very High"))) -> Medium | AB9: =IF(EmployeeData[[#This Row],[Attrition]]="Yes",1,0) -> 0 | AC9: =IF(EmployeeData[[#This Row],[Tenure Years]]<1,"Less than 1 Year",IF(EmployeeData[[#This Row],[Tenure Years]]<=3,"1-3 Years",IF(EmployeeData[[#This Row],[Tenure Years]]<=5,"4-5 Years",IF(EmployeeData[[#This Row],[Tenure Years]]<=10,"6-10 Years","More than 10 Years")))) -> 1-3 Years | AD9: =ROUND(AVERAGE(EmployeeData[[#This Row],[JobSatisfaction]],EmployeeData[[#This Row],[EnvironmentSatisfaction]],EmployeeData[[#This Row],[WorkLifeBalance]]),2) -> 3 | AE9: =IF(EmployeeData[[#This Row],[Satisfaction Score]]<2,"Low",IF(EmployeeData[[#This Row],[Satisfaction Score]]<3,"Medium","High")) -> High
A10: EMP1657 | B10: Logan Newton | C10: Female | D10: 30 | E10: Finance | F10: Accountant | G10: 44021 | H10: 62654 | I10: Divorced | J10: PhD | K10: Gurgaon | L10: Travel_Rarely | M10: 44 | N10: No | O10: 3 | P10: 1 | Q10: 1 | R10: 3 | S10: 3 | T10: 1 | U10: 21 | V10: Sheri Buchanan | W10: No | Y10: =IF(EmployeeData[[#This Row],[Age]]<25,"Under 25",IF(EmployeeData[[#This Row],[Age]]<=34,"25-34",IF(EmployeeData[[#This Row],[Age]]<=44,"35-44",IF(EmployeeData[[#This Row],[Age]]<=54,"45-54","55+")))) -> 25-34 | Z10: =DATEDIF(EmployeeData[[#This Row],[DateOfJoining]],IF(AND(EmployeeData[[#This Row],[Attrition]]="Yes",EmployeeData[[#This Row],[LastWorkingDate]]<>""),EmployeeData[[#This Row],[LastWorkingDate]],TODAY()),"Y") -> 6 | AA10: =IF(EmployeeData[[#This Row],[MonthlyIncome]]<30000,"Low",IF(EmployeeData[[#This Row],[MonthlyIncome]]<=60000,"Medium",IF(EmployeeData[[#This Row],[MonthlyIncome]]<=100000,"High","Very High"))) -> High | AB10: =IF(EmployeeData[[#This Row],[Attrition]]="Yes",1,0) -> 0 | AC10: =IF(EmployeeData[[#This Row],[Tenure Years]]<1,"Less than 1 Year",IF(EmployeeData[[#This Row],[Tenure Years]]<=3,"1-3 Years",IF(EmployeeData[[#This Row],[Tenure Years]]<=5,"4-5 Years",IF(EmployeeData[[#This Row],[Tenure Years]]<=10,"6-10 Years","More than 10 Years")))) -> 6-10 Years | AD10: =ROUND(AVERAGE(EmployeeData[[#This Row],[JobSatisfaction]],EmployeeData[[#This Row],[EnvironmentSatisfaction]],EmployeeData[[#This Row],[WorkLifeBalance]]),2) -> 1.67 | AE10: =IF(EmployeeData[[#This Row],[Satisfaction Score]]<2,"Low",IF(EmployeeData[[#This Row],[Satisfaction Score]]<3,"Medium","High")) -> Low
A11: EMP2114 | B11: Nicholas Johnston | C11: Female | D11: 39 | E11: Sales | F11: Sales Executive | G11: 44482 | H11: 41735 | I11: Single | J11: Not Specified | K11: Ahmedabad | L11: Travel_Rarely | M11: 2 | N11: No | O11: 2 | P11: 2 | Q11: 3 | R11: 4 | S11: 6 | T11: 6 | U11: 20 | V11: Brittany Clements MD | W11: No | Y11: =IF(EmployeeData[[#This Row],[Age]]<25,"Under 25",IF(EmployeeData[[#This Row],[Age]]<=34,"25-34",IF(EmployeeData[[#This Row],[Age]]<=44,"35-44",IF(EmployeeData[[#This Row],[Age]]<=54,"45-54","55+")))) -> 35-44 | Z11: =DATEDIF(EmployeeData[[#This Row],[DateOfJoining]],IF(AND(EmployeeData[[#This Row],[Attrition]]="Yes",EmployeeData[[#This Row],[LastWorkingDate]]<>""),EmployeeData[[#This Row],[LastWorkingDate]],TODAY()),"Y") -> 4 | AA11: =IF(EmployeeData[[#This Row],[MonthlyIncome]]<30000,"Low",IF(EmployeeData[[#This Row],[MonthlyIncome]]<=60000,"Medium",IF(EmployeeData[[#This Row],[MonthlyIncome]]<=100000,"High","Very High"))) -> Medium | AB11: =IF(EmployeeData[[#This Row],[Attrition]]="Yes",1,0) -> 0 | AC11: =IF(EmployeeData[[#This Row],[Tenure Years]]<1,"Less than 1 Year",IF(EmployeeData[[#This Row],[Tenure Years]]<=3,"1-3 Years",IF(EmployeeData[[#This Row],[Tenure Years]]<=5,"4-5 Years",IF(EmployeeData[[#This Row],[Tenure Years]]<=10,"6-10 Years","More than 10 Years")))) -> 4-5 Years | AD11: =ROUND(AVERAGE(EmployeeData[[#This Row],[JobSatisfaction]],EmployeeData[[#This Row],[EnvironmentSatisfaction]],EmployeeData[[#This Row],[WorkLifeBalance]]),2) -> 2.33 | AE11: =IF(EmployeeData[[#This Row],[Satisfaction Score]]<2,"Low",IF(EmployeeData[[#This Row],[Satisfaction Score]]<3,"Medium","High")) -> Medium
A12: EMP1035 | B12: Elizabeth Stewart | C12: Male | D12: 28 | E12: Research & Development | F12: Research Scientist | G12: 44882 | H12: 60333 | I12: Married | J12: Bachelor's | K12: Hyderabad | L12: Travel_Frequently | M12: 4 | N12: No | O12: 2 | P12: 4 | Q12: 2 | R12: 3 | S12: 0 | T12: 8 | U12: 21 | V12: Jimmy Murillo | W12: No | Y12: =IF(EmployeeData[[#This Row],[Age]]<25,"Under 25",IF(EmployeeData[[#This Row],[Age]]<=34,"25-34",IF(EmployeeData[[#This Row],[Age]]<=44,"35-44",IF(EmployeeData[[#This Row],[Age]]<=54,"45-54","55+")))) -> 25-34 | Z12: =DATEDIF(EmployeeData[[#This Row],[DateOfJoining]],IF(AND(EmployeeData[[#This Row],[Attrition]]="Yes",EmployeeData[[#This Row],[LastWorkingDate]]<>""),EmployeeData[[#This Row],[LastWorkingDate]],TODAY()),"Y") -> 3 | AA12: =IF(EmployeeData[[#This Row],[MonthlyIncome]]<30000,"Low",IF(EmployeeData[[#This Row],[MonthlyIncome]]<=60000,"Medium",IF(EmployeeData[[#This Row],[MonthlyIncome]]<=100000,"High","Very High"))) -> High | AB12: =IF(EmployeeData[[#This Row],[Attrition]]="Yes",1,0) -> 0 | AC12: =IF(EmployeeData[[#This Row],[Tenure Years]]<1,"Less than 1 Year",IF(EmployeeData[[#This Row],[Tenure Years]]<=3,"1-3 Years",IF(EmployeeData[[#This Row],[Tenure Years]]<=5,"4-5 Years",IF(EmployeeData[[#This Row],[Tenure Years]]<=10,"6-10 Years","More than 10 Years")))) -> 1-3 Years | AD12: =ROUND(AVERAGE(EmployeeData[[#This Row],[JobSatisfaction]],EmployeeData[[#This Row],[EnvironmentSatisfaction]],EmployeeData[[#This Row],[WorkLifeBalance]]),2) -> 2.67 | AE12: =IF(EmployeeData[[#This Row],[Satisfaction Score]]<2,"Low",IF(EmployeeData[[#This Row],[Satisfaction Score]]<3,"Medium","High")) -> Medium
A13: EMP1736 | B13: Margaret Erickson | C13: Female | D13: 31 | E13: Research & Development | F13: Research Scientist | G13: 41439 | H13: 111457 | I13: Single | J13: Diploma | K13: Noida | L13: Travel_Frequently | M13: 34 | N13: Yes | O13: 1 | P13: 2 | Q13: 1 | R13: 3 | S13: 0 | T13: 4 | U13: 11 | V13: Matthew Yoder | W13: Yes | X13: 45572 | Y13: =IF(EmployeeData[[#This Row],[Age]]<25,"Under 25",IF(EmployeeData[[#This Row],[Age]]<=34,"25-34",IF(EmployeeData[[#This Row],[Age]]<=44,"35-44",IF(EmployeeData[[#This Row],[Age]]<=54,"45-54","55+")))) -> 25-34 | Z13: =DATEDIF(EmployeeData[[#This Row],[DateOfJoining]],IF(AND(EmployeeData[[#This Row],[Attrition]]="Yes",EmployeeData[[#This Row],[LastWorkingDate]]<>""),EmployeeData[[#This Row],[LastWorkingDate]],TODAY()),"Y") -> 11 | AA13: =IF(EmployeeData[[#This Row],[MonthlyIncome]]<30000,"Low",IF(EmployeeData[[#This Row],[MonthlyIncome]]<=60000,"Medium",IF(EmployeeData[[#This Row],[MonthlyIncome]]<=100000,"High","Very High"))) -> Very High | AB13: =IF(EmployeeData[[#This Row],[Attrition]]="Yes",1,0) -> 1 | AC13: =IF(EmployeeData[[#This Row],[Tenure Years]]<1,"Less than 1 Year",IF(EmployeeData[[#This Row],[Tenure Years]]<=3,"1-3 Years",IF(EmployeeData[[#This Row],[Tenure Years]]<=5,"4-5 Years",IF(EmployeeData[[#This Row],[Tenure Years]]<=10,"6-10 Years","More than 10 Years")))) -> More than 10 Years | AD13: =ROUND(AVERAGE(EmployeeData[[#This Row],[JobSatisfaction]],EmployeeData[[#This Row],[EnvironmentSatisfaction]],EmployeeData[[#This Row],[WorkLifeBalance]]),2) -> 1.33 | AE13: =IF(EmployeeData[[#This Row],[Satisfaction Score]]<2,"Low",IF(EmployeeData[[#This Row],[Satisfaction Score]]<3,"Medium","High")) -> Low
A14: EMP1064 | B14: David Benson | C14: Female | D14: 40 | E14: Sales | F14: Sales Manager | G14: 44635 | H14: 57034 | I14: Married | J14: Bachelor's | K14: Mumbai | L14: Travel_Rarely | M14: 22 | N14: No | O14: 3 | P14: 1 | Q14: 4 | R14: 2 | S14: 1 | T14: 8 | U14: 22 | V14: Jason Daniels | W14: No | Y14: =IF(EmployeeData[[#This Row],[Age]]<25,"Under 25",IF(EmployeeData[[#This Row],[Age]]<=34,"25-34",IF(EmployeeData[[#This Row],[Age]]<=44,"35-44",IF(EmployeeData[[#This Row],[Age]]<=54,"45-54","55+")))) -> 35-44 | Z14: =DATEDIF(EmployeeData[[#This Row],[DateOfJoining]],IF(AND(EmployeeData[[#This Row],[Attrition]]="Yes",EmployeeData[[#This Row],[LastWorkingDate]]<>""),EmployeeData[[#This Row],[LastWorkingDate]],TODAY()),"Y") -> 4 | AA14: =IF(EmployeeData[[#This Row],[MonthlyIncome]]<30000,"Low",IF(EmployeeData[[#This Row],[MonthlyIncome]]<=60000,"Medium",IF(EmployeeData[[#This Row],[MonthlyIncome]]<=100000,"High","Very High"))) -> Medium | AB14: =IF(EmployeeData[[#This Row],[Attrition]]="Yes",1,0) -> 0 | AC14: =IF(EmployeeData[[#This Row],[Tenure Years]]<1,"Less than 1 Year",IF(EmployeeData[[#This Row],[Tenure Years]]<=3,"1-3 Years",IF(EmployeeData[[#This Row],[Tenure Years]]<=5,"4-5 Years",IF(EmployeeData[[#This Row],[Tenure Years]]<=10,"6-10 Years","More than 10 Years")))) -> 4-5 Years | AD14: =ROUND(AVERAGE(EmployeeData[[#This Row],[JobSatisfaction]],EmployeeData[[#This Row],[EnvironmentSatisfaction]],EmployeeData[[#This Row],[WorkLifeBalance]]),2) -> 2.67 | AE14: =IF(EmployeeData[[#This Row],[Satisfaction Score]]<2,"Low",IF(EmployeeData[[#This Row],[Satisfaction Score]]<3,"Medium","High")) -> Medium
A15: EMP1642 | B15: Jonathan Ellis | C15: Male | D15: 39 | E15: Sales | F15: Sales Representative | G15: 45833 | H15: 75286 | I15: Divorced | J15: PhD | K15: Delhi | L15: Non-Travel | M15: 39 | N15: No | O15: 2 | P15: 4 | Q15: 3 | R15: 4 | S15: 2 | T15: 4 | U15: 19 | V15: Joseph Cook | W15: Yes | X15: 45842 | Y15: =IF(EmployeeData[[#This Row],[Age]]<25,"Under 25",IF(EmployeeData[[#This Row],[Age]]<=34,"25-34",IF(EmployeeData[[#This Row],[Age]]<=44,"35-44",IF(EmployeeData[[#This Row],[Age]]<=54,"45-54","55+")))) -> 35-44 | Z15: =DATEDIF(EmployeeData[[#This Row],[DateOfJoining]],IF(AND(EmployeeData[[#This Row],[Attrition]]="Yes",EmployeeData[[#This Row],[LastWorkingDate]]<>""),EmployeeData[[#This Row],[LastWorkingDate]],TODAY()),"Y") -> 0 | AA15: =IF(EmployeeData[[#This Row],[MonthlyIncome]]<30000,"Low",IF(EmployeeData[[#This Row],[MonthlyIncome]]<=60000,"Medium",IF(EmployeeData[[#This Row],[MonthlyIncome]]<=100000,"High","Very High"))) -> High | AB15: =IF(EmployeeData[[#This Row],[Attrition]]="Yes",1,0) -> 1 | AC15: =IF(EmployeeData[[#This Row],[Tenure Years]]<1,"Less than 1 Year",IF(EmployeeData[[#This Row],[Tenure Years]]<=3,"1-3 Years",IF(EmployeeData[[#This Row],[Tenure Years]]<=5,"4-5 Years",IF(EmployeeData[[#This Row],[Tenure Years]]<=10,"6-10 Years","More than 10 Years")))) -> Less than 1 Year | AD15: =ROUND(AVERAGE(EmployeeData[[#This Row],[JobSatisfaction]],EmployeeData[[#This Row],[EnvironmentSatisfaction]],EmployeeData[[#This Row],[WorkLifeBalance]]),2) -> 3 | AE15: =IF(EmployeeData[[#This Row],[Satisfaction Score]]<2,"Low",IF(EmployeeData[[#This Row],[Satisfaction Score]]<3,"Medium","High")) -> High
A16: EMP1762 | B16: Anna Cox | C16: Male | D16: 37 | E16: Human Resources | F16: Hr Manager | G16: 44933 | H16: 65329 | I16: Single | J16: Bachelor's | K16: Bangalore | L16: Non-Travel | M16: 37 | N16: No | O16: 4 | P16: 2 | Q16: 4 | R16: 4 | S16: 0 | T16: 7 | U16: 16 | V16: Colleen Townsend | W16: No | Y16: =IF(EmployeeData[[#This Row],[Age]]<25,"Under 25",IF(EmployeeData[[#This Row],[Age]]<=34,"25-34",IF(EmployeeData[[#This Row],[Age]]<=44,"35-44",IF(EmployeeData[[#This Row],[Age]]<=54,"45-54","55+")))) -> 35-44 | Z16: =DATEDIF(EmployeeData[[#This Row],[DateOfJoining]],IF(AND(EmployeeData[[#This Row],[Attrition]]="Yes",EmployeeData[[#This Row],[LastWorkingDate]]<>""),EmployeeData[[#This Row],[LastWorkingDate]],TODAY()),"Y") -> 3 | AA16: =IF(EmployeeData[[#This Row],[MonthlyIncome]]<30000,"Low",IF(EmployeeData[[#This Row],[MonthlyIncome]]<=60000,"Medium",IF(EmployeeData[[#This Row],[MonthlyIncome]]<=100000,"High","Very High"))) -> High | AB16: =IF(EmployeeData[[#This Row],[Attrition]]="Yes",1,0) -> 0 | AC16: =IF(EmployeeData[[#This Row],[Tenure Years]]<1,"Less than 1 Year",IF(EmployeeData[[#This Row],[Tenure Years]]<=3,"1-3 Years",IF(EmployeeData[[#This Row],[Tenure Years]]<=5,"4-5 Years",IF(EmployeeData[[#This Row],[Tenure Years]]<=10,"6-10 Years","More than 10 Years")))) -> 1-3 Years | AD16: =ROUND(AVERAGE(EmployeeData[[#This Row],[JobSatisfaction]],EmployeeData[[#This Row],[EnvironmentSatisfaction]],EmployeeData[[#This Row],[WorkLifeBalance]]),2) -> 3.33 | AE16: =IF(EmployeeData[[#This Row],[Satisfaction Score]]<2,"Low",IF(EmployeeData[[#This Row],[Satisfaction Score]]<3,"Medium","High")) -> High
A17: EMP1928 | B17: Luke Martinez | C17: Female | D17: 26 | E17: It | F17: It Support | G17: 42007 | H17: 96042 | I17: Single | J17: High School | K17: Hyderabad | L17: Non-Travel | M17: 16 | N17: Yes | O17: 4 | P17: 1 | Q17: 3 | R17: 3 | S17: 2 | T17: 5 | U17: 21 | V17: Gerald Kelly | W17: No | Y17: =IF(EmployeeData[[#This Row],[Age]]<25,"Under 25",IF(EmployeeData[[#This Row],[Age]]<=34,"25-34",IF(EmployeeData[[#This Row],[Age]]<=44,"35-44",IF(EmployeeData[[#This Row],[Age]]<=54,"45-54","55+")))) -> 25-34 | Z17: =DATEDIF(EmployeeData[[#This Row],[DateOfJoining]],IF(AND(EmployeeData[[#This Row],[Attrition]]="Yes",EmployeeData[[#This Row],[LastWorkingDate]]<>""),EmployeeData[[#This Row],[LastWorkingDate]],TODAY()),"Y") -> 11 | AA17: =IF(EmployeeData[[#This Row],[MonthlyIncome]]<30000,"Low",IF(EmployeeData[[#This Row],[MonthlyIncome]]<=60000,"Medium",IF(EmployeeData[[#This Row],[MonthlyIncome]]<=100000,"High","Very High"))) -> High | AB17: =IF(EmployeeData[[#This Row],[Attrition]]="Yes",1,0) -> 0 | AC17: =IF(EmployeeData[[#This Row],[Tenure Years]]<1,"Less than 1 Year",IF(EmployeeData[[#This Row],[Tenure Years]]<=3,"1-3 Years",IF(EmployeeData[[#This Row],[Tenure Years]]<=5,"4-5 Years",IF(EmployeeData[[#This Row],[Tenure Years]]<=10,"6-10 Years","More than 10 Years")))) -> More than 10 Years | AD17: =ROUND(AVERAGE(EmployeeData[[#This Row],[JobSatisfaction]],EmployeeData[[#This Row],[EnvironmentSatisfaction]],EmployeeData[[#This Row],[WorkLifeBalance]]),2) -> 2.67 | AE17: =IF(EmployeeData[[#This Row],[Satisfaction Score]]<2,"Low",IF(EmployeeData[[#This Row],[Satisfaction Score]]<3,"Medium","High")) -> Medium
A18: EMP1455 | B18: Joseph Williams | C18: Female | D18: 19 | E18: Human Resources | F18: Hr Executive | G18: 46206 | H18: 29667 | I18: Married | J18: Master's | K18: Mumbai | L18: Non-Travel | M18: 32 | N18: No | O18: 4 | P18: 1 | Q18: 2 | R18: 3 | S18: 4 | T18: 8 | U18: 13 | V18: Alicia Norris | W18: Yes | X18: 46245 | Y18: =IF(EmployeeData[[#This Row],[Age]]<25,"Under 25",IF(EmployeeData[[#This Row],[Age]]<=34,"25-34",IF(EmployeeData[[#This Row],[Age]]<=44,"35-44",IF(EmployeeData[[#This Row],[Age]]<=54,"45-54","55+")))) -> Under 25 | Z18: =DATEDIF(EmployeeData[[#This Row],[DateOfJoining]],IF(AND(EmployeeData[[#This Row],[Attrition]]="Yes",EmployeeData[[#This Row],[LastWorkingDate]]<>""),EmployeeData[[#This Row],[LastWorkingDate]],TODAY()),"Y") -> 0 | AA18: =IF(EmployeeData[[#This Row],[MonthlyIncome]]<30000,"Low",IF(EmployeeData[[#This Row],[MonthlyIncome]]<=60000,"Medium",IF(EmployeeData[[#This Row],[MonthlyIncome]]<=100000,"High","Very High"))) -> Low | AB18: =IF(EmployeeData[[#This Row],[Attrition]]="Yes",1,0) -> 1 | AC18: =IF(EmployeeData[[#This Row],[Tenure Years]]<1,"Less than 1 Year",IF(EmployeeData[[#This Row],[Tenure Years]]<=3,"1-3 Years",IF(EmployeeData[[#This Row],[Tenure Years]]<=5,"4-5 Years",IF(EmployeeData[[#This Row],[Tenure Years]]<=10,"6-10 Years","More than 10 Years")))) -> Less than 1 Year | AD18: =ROUND(AVERAGE(EmployeeData[[#This Row],[JobSatisfaction]],EmployeeData[[#This Row],[EnvironmentSatisfaction]],EmployeeData[[#This Row],[WorkLifeBalance]]),2) -> 2.33 | AE18: =IF(EmployeeData[[#This Row],[Satisfaction Score]]<2,"Low",IF(EmployeeData[[#This Row],[Satisfaction Score]]<3,"Medium","High")) -> Medium
A19: EMP1356 | B19: Pamela Best | C19: Female | D19: 41 | E19: Sales | F19: Not Specified | G19: 44983 | H19: 86947 | I19: Divorced | J19: Master's | K19: Mumbai | L19: Travel_Frequently | M19: 2 | N19: Yes | O19: 2 | P19: 3 | Q19: 3 | R19: 3 | S19: 5 | T19: 2 | U19: 14 | V19: Not Specified | W19: No | Y19: =IF(EmployeeData[[#This Row],[Age]]<25,"Under 25",IF(EmployeeData[[#This Row],[Age]]<=34,"25-34",IF(EmployeeData[[#This Row],[Age]]<=44,"35-44",IF(EmployeeData[[#This Row],[Age]]<=54,"45-54","55+")))) -> 35-44 | Z19: =DATEDIF(EmployeeData[[#This Row],[DateOfJoining]],IF(AND(EmployeeData[[#This Row],[Attrition]]="Yes",EmployeeData[[#This Row],[LastWorkingDate]]<>""),EmployeeData[[#This Row],[LastWorkingDate]],TODAY()),"Y") -> 3 | AA19: =IF(EmployeeData[[#This Row],[MonthlyIncome]]<30000,"Low",IF(EmployeeData[[#This Row],[MonthlyIncome]]<=60000,"Medium",IF(EmployeeData[[#This Row],[MonthlyIncome]]<=100000,"High","Very High"))) -> High | AB19: =IF(EmployeeData[[#This Row],[Attrition]]="Yes",1,0) -> 0 | AC19: =IF(EmployeeData[[#This Row],[Tenure Years]]<1,"Less than 1 Year",IF(EmployeeData[[#This Row],[Tenure Years]]<=3,"1-3 Years",IF(EmployeeData[[#This Row],[Tenure Years]]<=5,"4-5 Years",IF(EmployeeData[[#This Row],[Tenure Years]]<=10,"6-10 Years","More than 10 Years")))) -> 1-3 Years | AD19: =ROUND(AVERAGE(EmployeeData[[#This Row],[JobSatisfaction]],EmployeeData[[#This Row],[EnvironmentSatisfaction]],EmployeeData[[#This Row],[WorkLifeBalance]]),2) -> 2.67 | AE19: =IF(EmployeeData[[#This Row],[Satisfaction Score]]<2,"Low",IF(EmployeeData[[#This Row],[Satisfaction Score]]<3,"Medium","High")) -> Medium
A20: EMP2073 | B20: John Davidson | C20: Female | D20: 30 | E20: Finance | F20: Auditor | G20: 43991 | H20: 134761 | I20: Single | J20: PhD | K20: Hyderabad | L20: Travel_Frequently | M20: 34 | N20: No | O20: 1 | P20: 2 | Q20: 4 | R20: 4 | S20: 6 | T20: 3 | U20: 18 | V20: Andrew Dorsey | W20: No | Y20: =IF(EmployeeData[[#This Row],[Age]]<25,"Under 25",IF(EmployeeData[[#This Row],[Age]]<=34,"25-34",IF(EmployeeData[[#This Row],[Age]]<=44,"35-44",IF(EmployeeData[[#This Row],[Age]]<=54,"45-54","55+")))) -> 25-34 | Z20: =DATEDIF(EmployeeData[[#This Row],[DateOfJoining]],IF(AND(EmployeeData[[#This Row],[Attrition]]="Yes",EmployeeData[[#This Row],[LastWorkingDate]]<>""),EmployeeData[[#This Row],[LastWorkingDate]],TODAY()),"Y") -> 6 | AA20: =IF(EmployeeData[[#This Row],[MonthlyIncome]]<30000,"Low",IF(EmployeeData[[#This Row],[MonthlyIncome]]<=60000,"Medium",IF(EmployeeData[[#This Row],[MonthlyIncome]]<=100000,"High","Very High"))) -> Very High | AB20: =IF(EmployeeData[[#This Row],[Attrition]]="Yes",1,0) -> 0 | AC20: =IF(EmployeeData[[#This Row],[Tenure Years]]<1,"Less than 1 Year",IF(EmployeeData[[#This Row],[Tenure Years]]<=3,"1-3 Years",IF(EmployeeData[[#This Row],[Tenure Years]]<=5,"4-5 Years",IF(EmployeeData[[#This Row],[Tenure Years]]<=10,"6-10 Years","More than 10 Years")))) -> 6-10 Years | AD20: =ROUND(AVERAGE(EmployeeData[[#This Row],[JobSatisfaction]],EmployeeData[[#This Row],[EnvironmentSatisfaction]],EmployeeData[[#This Row],[WorkLifeBalance]]),2) -> 2.33 | AE20: =IF(EmployeeData[[#This Row],[Satisfaction Score]]<2,"Low",IF(EmployeeData[[#This Row],[Satisfaction Score]]<3,"Medium","High")) -> Medium
A21: EMP1446 | B21: Jason Hudson | C21: Female | D21: 38 | E21: It | F21: Devops Engineer | G21: 45726 | H21: 132335 | I21: Married | J21: Bachelor's | K21: Chennai | L21: Travel_Rarely | M21: 1 | N21: Yes | O21: 3 | P21: 3 | Q21: 4 | R21: 2 | S21: 6 | T21: 2 | U21: 21 | V21: Mike Maxwell | W21: Yes | X21: 45972 | Y21: =IF(EmployeeData[[#This Row],[Age]]<25,"Under 25",IF(EmployeeData[[#This Row],[Age]]<=34,"25-34",IF(EmployeeData[[#This Row],[Age]]<=44,"35-44",IF(EmployeeData[[#This Row],[Age]]<=54,"45-54","55+")))) -> 35-44 | Z21: =DATEDIF(EmployeeData[[#This Row],[DateOfJoining]],IF(AND(EmployeeData[[#This Row],[Attrition]]="Yes",EmployeeData[[#This Row],[LastWorkingDate]]<>""),EmployeeData[[#This Row],[LastWorkingDate]],TODAY()),"Y") -> 0 | AA21: =IF(EmployeeData[[#This Row],[MonthlyIncome]]<30000,"Low",IF(EmployeeData[[#This Row],[MonthlyIncome]]<=60000,"Medium",IF(EmployeeData[[#This Row],[MonthlyIncome]]<=100000,"High","Very High"))) -> Very High | AB21: =IF(EmployeeData[[#This Row],[Attrition]]="Yes",1,0) -> 1 | AC21: =IF(EmployeeData[[#This Row],[Tenure Years]]<1,"Less than 1 Year",IF(EmployeeData[[#This Row],[Tenure Years]]<=3,"1-3 Years",IF(EmployeeData[[#This Row],[Tenure Years]]<=5,"4-5 Years",IF(EmployeeData[[#This Row],[Tenure Years]]<=10,"6-10 Years","More than 10 Years")))) -> Less than 1 Year | AD21: =ROUND(AVERAGE(EmployeeData[[#This Row],[JobSatisfaction]],EmployeeData[[#This Row],[EnvironmentSatisfaction]],EmployeeData[[#This Row],[WorkLifeBalance]]),2) -> 3.33 | AE21: =IF(EmployeeData[[#This Row],[Satisfaction Score]]<2,"Low",IF(EmployeeData[[#This Row],[Satisfaction Score]]<3,"Medium","High")) -> High
A22: EMP1351 | B22: Angelica Garcia | C22: Male | D22: 33 | E22: Research & Development | F22: Lab Technician | G22: 44886 | H22: 69167 | I22: Single | J22: Bachelor's | K22: Chennai | L22: Travel_Frequently | M22: 24 | N22: Yes | O22: 1 | P22: 4 | Q22: 1 | R22: 1 | S22: 1 | T22: 7 | U22: 23 | V22: Not Specified | W22: Yes | X22: 45699 | Y22: =IF(EmployeeData[[#This Row],[Age]]<25,"Under 25",IF(EmployeeData[[#This Row],[Age]]<=34,"25-34",IF(EmployeeData[[#This Row],[Age]]<=44,"35-44",IF(EmployeeData[[#This Row],[Age]]<=54,"45-54","55+")))) -> 25-34 | Z22: =DATEDIF(EmployeeData[[#This Row],[DateOfJoining]],IF(AND(EmployeeData[[#This Row],[Attrition]]="Yes",EmployeeData[[#This Row],[LastWorkingDate]]<>""),EmployeeData[[#This Row],[LastWorkingDate]],TODAY()),"Y") -> 2 | AA22: =IF(EmployeeData[[#This Row],[MonthlyIncome]]<30000,"Low",IF(EmployeeData[[#This Row],[MonthlyIncome]]<=60000,"Medium",IF(EmployeeData[[#This Row],[MonthlyIncome]]<=100000,"High","Very High"))) -> High | AB22: =IF(EmployeeData[[#This Row],[Attrition]]="Yes",1,0) -> 1 | AC22: =IF(EmployeeData[[#This Row],[Tenure Years]]<1,"Less than 1 Year",IF(EmployeeData[[#This Row],[Tenure Years]]<=3,"1-3 Years",IF(EmployeeData[[#This Row],[Tenure Years]]<=5,"4-5 Years",IF(EmployeeData[[#This Row],[Tenure Years]]<=10,"6-10 Years","More than 10 Years")))) -> 1-3 Years | AD22: =ROUND(AVERAGE(EmployeeData[[#This Row],[JobSatisfaction]],EmployeeData[[#This Row],[EnvironmentSatisfaction]],EmployeeData[[#This Row],[WorkLifeBalance]]),2) -> 2 | AE22: =IF(EmployeeData[[#This Row],[Satisfaction Score]]<2,"Low",IF(EmployeeData[[#This Row],[Satisfaction Score]]<3,"Medium","High")) -> Medium
